Workbook

Sheet Dashboard
A1: Case manager | B1: Malak | H1: Row Labels | I1: Count of Joining Date
A2: Claims Status | B2: Claimable | H2: Dina | I2: 16
A3: Dispute | B3: (All) | H3: Meaad | I3: 25
H4: Malak | I4: 9
A5: Row Labels | H5: Husain | I5: 38
A6: JCP/26/286008 | H6: Zainab Mattar | I6: 11
A7: JCP/25/167732 | H7: Mahdi | I7: 3
A8: JCP/24/095374 | H8: Grand Total | I8: 102
A9: JCP/25/183265
A10: JCP/24/146053
A11: JCP/24/098208
A12: Grand Total

Sheet Placements 25
A1: SL No. | B1: Case manager | C1: Ref No | D1: Name | E1: CPR | F1: Joining Date | G1: MoL | H1: Long MoL +3 Years | I1: Gender | J1: Education | K1: Salary | L1: Position | M1: Company | N1: Employer CR No. | O1: Employement Type | P1: Comments
A2: 14 | B2: Husain | C2: JCP/25/219615 | D2: HUSAIN ABDULMONEM HU MOTHANNA | E2: 010207910 | F2: 46005 | G2: Yes | I2: Male | J2: High School | K2: 450 | L2: Office Assistant | M2: ALMOAYYED CLEANING & MAINTENANCE W.L.L. | N2: 47533-1 | O2: Full time Direct Employment | P2: Payment without VAT
A3: 15 | B3: Husain | C3: JCP/25/232927 | D3: SAYED MOHAMED SAEED HASAN ALAWI | E3: 920401961 | F3: 46005 | G3: Yes | I3: Male | J3: Bachelors + | K3: 500 | L3: Sales Executive | M3: ALMOAYYED CONTRACTING GROUP W.L.L. | N3: 43090-1 | O3: Full time Direct Employment
A4: 16 | B4: Husain | C4: JCP/25/214227 | D4: FATEMA WALEED HASAN SHOWIATER | E4: 020905904 | F4: 46006 | G4: Yes | I4: Female | J4: Bachelors + | K4: 500 | L4: Trainee Mechanical engineer | M4: ALMOAYYED AIR CONDITIONING W.L.L. | N4: 76980-1 | O4: Full time Direct Employment | P4: Payment without VAT
A5: 17 | B5: Husain | C5: JCP/25/212208 | D5: WALAA ISA A. HASAN | E5: 990900045 | F5: 45865 | G5: Yes | I5: Female | J5: Bachelors + | K5: 700 | L5: Account Manager Specialist | M5: Student Plaform | N5: 127080-1 | O5: Full time Direct Employment | P5: Payment without VAT
A6: 18 | B6: Meaad | C6: JCP/25/223039 | D6: SAYED ALI HASHEM E. ALQASSAB | E6: 70809119 | F6: 45956 | G6: Yes | I6: Male | J6: High School | K6: 350 | L6: Driver | M6: SIMPLEX AL MOAYYED W.L.L | N6: 58313-1 | O6: Full time Direct Employment | P6: Payment without VAT
A7: 20 | B7: Dina | C7: JCP/25/233782 | D7: FATEMA JAAFAR MOHAMED FARHAN | E7: 040601854 | F7: 45939 | G7: Yes | I7: Female | J7: High School | K7: 350 | L7: Sales Lady | M7: Femi 9 | N7: 49089-3 | O7: Full time Direct Employment
A8: 29 | B8: Husain | C8: JCP/25/170479 | D8: Ali hasan Alaswami | E8: 930904079 | F8: 45692 | G8: Yes | H8: Yes | I8: Male | J8: High School | K8: 450 | L8: Safety officer | M8: Rafco | N8: 1856-1 | O8: Full time Direct Employment | P8: Payment without VAT
A9: 30 | B9: Husain | C9: JCP/25/213845 | D9: Sara Jamal Ahmed | E9: 970303629 | F9: 45874 | I9: Female | J9: Bachelors + | K9: 500 | L9: Consultant | M9: Propel Consult | N9: 75091-1 | O9: Insourced to Service Provider | P9: Payment without VAT
A10: 32 | B10: Husain | C10: JCP/25/170060 | D10: SALMAN ADEL OUN JASIM | E10: 050201182 | F10: 45697 | G10: Yes | I10: Male | J10: High School | K10: 350 | L10: Driver | M10: DRAGON BEACH HOTEL W.L.L | N10: 170835-2 | O10: Full time Direct Employment | P10: Payment without VAT
A11: 42 | B11: Husain | C11: JCP/25/213261 | D11: AMMAR SALEH HASAN AHMED ALI | E11: 000305910 | F11: 45893 | G11: Yes | I11: Male | J11: Diploma | K11: 450 | L11: Machine operator | M11: ARLA FOODS W.L.L | N11: 127867-1 | O11: Full time Direct Employment | P11: Payment without VAT
A12: 43 | B12: Husain | C12: JCP/25/217089 | D12: ALI HUSAIN ABDULLA KAD FARDAN | E12: 030400686 | F12: 45886 | G12: Yes | I12: Male | J12: High School | K12: 350 | L12: Security Cum Bell Boy | M12: Almanzil hotel | N12: 186174-1 | O12: Full time Direct Employment | P12: Payment without VAT
A13: 47 | B13: Husain | C13: JCP/25/171258 | D13: Noora Faqir | E13: 930911571 | F13: 45721 | I13: Female | J13: High School | K13: 350 | L13: Cashier/ Sales consultant | M13: BAHRAIN FINANCING COMPANY | N13: 35-10 | O13: Full time Direct Employment | P13: Payment without VAT
A14: 49 | B14: Husain | C14: JCP/25/153757 | D14: Sayed Moosa Mahdi Alawi Mohsen Ahmed | E14: 020100868 | F14: 45725 | I14: Male | J14: High School | K14: 350 | L14: Electrical technician | M14: IOT BAHRAIN TRADING | N14: 148642-1 | O14: Full time Direct Employment | P14: Payment without VAT
A15: 50 | B15: Husain | C15: JCP/24/096845 | D15: KARAR HUSAM ALI YATEEM | E15: 980405866 | F15: 45911 | G15: Yes | H15: Yes | I15: Male | J15: High School | K15: 500 | L15: Partner Care agent | M15: NINJA SUPPORT W.L.L | N15: 184823-1 | O15: Full time Direct Employment | P15: Payment without VAT
A16: 51 | B16: Husain | C16: JCP/25/225850 | D16: HASAN FADHEL HASAN ISMAEEL ALI | E16: 970102917 | F16: 45914 | I16: Male | J16: Bachelors + | K16: 500 | L16: Electronic engineer | M16: IOT BAHRAIN TRADING | N16: 148642-1 | O16: Full time Direct Employment | P16: Payment without VAT
A17: 52 | B17: Husain | C17: JCP/25/173504 | D17: Shuaib hasan Rustam | E17: 940205432 | F17: 45739 | G17: Yes | H17: Yes | I17: Male | J17: High School | K17: 400 | L17: Coordinator | M17: RAFFA INDUSTRIAL SERVICES W.L.L | N17: 1856-2 | O17: Full time Direct Employment | P17: Payment without VAT
A18: 53 | B18: Husain | C18: JCP/25/217425 | D18: ALI SALMAN HASAN ALI | E18: 960800360 | F18: 45922 | G18: Yes | H18: Yes | I18: Male | J18: High School | K18: 400 | L18: Forklift operator | M18: KONEXUS ALUMINIUM INTERNATIONAL CO. W.L.L | N18: 116589-1 | O18: Full time Direct Employment | P18: Payment without VAT
A19: 54 | B19: Husain | C19: JCP/24/047875 | D19: AMMAR SAYED YASER SAEED MOHAMED | E19: 960507680 | F19: 45922 | G19: Yes | H19: Yes | I19: Male | J19: Bachelors + | K19: 600 | L19: Partnership Specialist | M19: STUDENT PLATFORM W.L.L. | N19: 127080-1 | O19: Full time Direct Employment | P19: Payment without VAT
A20: 55 | B20: Meaad | C20: JCP/25/229307 | D20: Bader Abdulnabi Ebrahim | E20: 10306587 | F20: 45921 | G20: Yes | H20: Yes | I20: Male | J20: Bachelors + | K20: 378 | L20: Sales Executive | M20: BAHRAIN DUTY FREE CO. WLL | N20: 119146-1 | O20: Full time Direct Employment
A21: 56 | B21: Meaad | C21: JCP/25/174221 | D21: فاطمه حسن الليث | E21: 920300600 | F21: 45921 | I21: Female | J21: Bachelors + | K21: 500 | L21: Consultant | M21: GIG | N21: 75091-1
A22: 57 | B22: Husain | C22: JCP/25/180485 | D22: ساره ساتر | E22: 010306420 | F22: 45740 | G22: Yes | H22: Yes | I22: Female | J22: Bachelors + | K22: 500 | L22: Accountant | M22: KONEXUS ALUMINIUM INTERNATIONAL CO. W.L.L | N22: 116589-1 | O22: Full time Direct Employment | P22: Payment without VAT
A23: 58 | B23: Meaad | C23: JCP/25/194119 | D23: MAHDI MOHAMED MAHDI ALI | E23: 891103503 | F23: 45792 | I23: Male | M23: DRAGON BEACH HOTEL W.L.L | N23: 170835-2 | O23: Full time Direct Employment
A24: 59 | B24: Malak | C24: JCP/25/178761 | D24: MAJED MOHAMED ALI MOHSEN ZABAR | E24: 840201451 | F24: 45922 | G24: Yes | I24: Male | J24: Diploma | K24: 1200 | L24: Business Development Manager | M24: HAAND SOLUTIONS LTDA W.L.L | N24: 167652-01 | O24: Full time Direct Employment | P24: 6 Months Payment
A25: 60 | B25: Zainab Mattar | C25: JCP/25/231016 | D25: KHADIJA FAISAL ALIJASI AHMED | E25: 020608268 | F25: 45927 | G25: No | H25: No | I25: Female | J25: High School | K25: 350 | L25: Sales Lady | M25: FEMI 9 | N25: 49089-3 | O25: Full time Direct Employment
A26: 61 | B26: Meaad | C26: JCP/25/190585 | D26: ZAINAB MOHAMED GHULOOM ALI | E26: 1203282 | F26: 45811 | G26: Yes | I26: Female | J26: Bachelors + | K26: 500 | L26: sales designer | M26: ALMA KITCHENS FACTORY W.L.L | N26: 11017-10 | O26: Full time Direct Employment
A27: 64 | B27: Meaad | C27: JCP/25/195286 | D27: HASAN AQEEL ALI HASAN ALJESHI | E27: 950405051 | F27: 45819 | G27: Yes | I27: Male | J27: High School | M27: AHMED MANSOOR ALAALI | N27: 571-2 | O27: Full time Direct Employment
A28: 65 | B28: Dina | C28: JCP/24/094062 | D28: sayed ali noordeen ali | E28: 970303335 | F28: 46012 | G28: Yes | H28: Yes | I28: Male | J28: Diploma | K28: 700 | L28: Safety officer | M28: GULF TOBACCO COMPANY. W.L.L | N28: 145777-1 | O28: Full time Direct Employment
A29: 97 | B29: Husain | C29: JCP/24/142442 | D29: SAYED ALAA MOOSA MOHAMED FADHEL | E29: 890704791 | F29: 45931 | I29: Male | J29: Bachelors + | K29: 500 | L29: Sales officer | M29: MENWIN BUSINESS CONSULTANTS W.L.L | N29: 163331-1 | O29: Full time Direct Employment | P29: Payment without VAT, payment done for 6 months
A30: 98 | B30: Husain | C30: JCP/25/233173 | D30: KHALIFA EBRAHIM K. SAAD | E30: 890201641 | F30: 45935 | G30: Yes | I30: Male | J30: High School | K30: 350 | L30: Security officer | M30: THE K - HOTEL W.L.L | N30: 74418-1 | O30: Full time Direct Employment | P30: Payment without VAT, payment done for 6 months
A31: 99 | B31: Husain | C31: JCP/25/244587 | D31: EBRAHIM NAEEM A. MARHOON | E31: 920801471 | F31: 45939 | G31: Yes | I31: Male | J31: High School | K31: 420 | L31: Trainee- HSE officer | M31: ALMOAYYED CONTRACTING GROUP W.L.L. | N31: 43090-1 | O31: Full time Direct Employment | P31: payment done for 6 months
A32: 100 | B32: Husain | C32: JCP/24/147404 | D32: ALI HAFEDH ALI BUKAMAL | E32: 961204559 | F32: 45942 | G32: Yes | I32: Male | J32: Bachelors + | K32: 500 | L32: Admin officer | M32: BAHRAIN INSTITUTE FOR PEARLS AND GEMSTONES (DANAT) W.L.L | N32: 112090-1 | O32: Full time Direct Employment | P32: Payment without VAT, payment done for 6 months
A33: 101 | B33: Husain | C33: JCP/25/244921 | D33: Firas Ali Abdulla | E33: 990102378 | F33: 45942 | I33: Male | J33: Bachelors + | K33: 850 | L33: Marketing Manager | M33: STUDENT PLATFORM W.L.L. | N33: 127080-1 | O33: Full time Direct Employment | P33: payment done for 6 months
A34: 102 | B34: Husain | C34: JCP/24/109221 | D34: ALI GHULAM MOHAMED AMEERI | E34: 941113825 | F34: 45931 | G34: Yes | H34: Yes | I34: Male | J34: Bachelors + | K34: 500 | L34: sales executive | M34: MENWIN BUSINESS CONSULTANTS W.L.L | O34: Full time Direct Employment | P34: Payment without VAT, payment done for 6 months
A35: 103 | B35: Husain | C35: JCP/25/184255 | D35: hasan mohamed taqi | E35: 980308771 | F35: 45760 | I35: Male | J35: Bachelors + | K35: 500 | L35: Planning technician | M35: RAFFA INDUSTRIAL SERVICES W.L.L | N35: 1856-01 | O35: Full time Direct Employment | P35: Payment without VAT, payment done for 12 months
A36: 105 | B36: Husain | C36: JCP/25/163920 | D36: MOHAMED ALI NAJIMO ALRAYASHI | E36: 980903750 | F36: 45763 | G36: Yes | I36: Male | J36: Bachelors + | K36: 500 | L36: Engineering Aid | M36: RAFFA INDUSTRIAL SERVICES W.L.L | N36: 1856-01 | O36: Full time Direct Employment | P36: Payment without VAT, payment done for 12 months
A37: 106 | B37: Husain | C37: JCP/25/176279 | D37: AWADH ATEF M. ALATEF | E37: 050915215 | F37: 45741 | I37: Male | J37: High School | K37: 350 | L37: worker | M37: Bahrain pack | N37: 29242-01 | O37: Full time Direct Employment | P37: Payment without VAT, payment done for 12 months
A38: 107 | B38: Husain | C38: JCP/25/181964 | D38: SAMAR AMER HASAN ZAINUDDIN | E38: 951206605 | F38: 45751 | I38: Female | J38: Bachelors + | K38: 820 | L38: SUPERVISOR | M38: CHALHOUB & BUHINDI CO. W.L.L | N38: 39216-1 | O38: Full time Direct Employment | P38: Payment without VAT, payment done for 12 months
A39: 108 | B39: Husain | C39: JCP/24/141182 | D39: SAYED HASAN HAMZA HUSAIN JAAFAR | E39: 920500820 | F39: 45767 | I39: Male | J39: Bachelors + | K39: 700 | L39: Adminstrator | M39: WE GROW CONSULTANCY | N39: 117683-2 | O39: Full time Direct Employment | P39: Payment without VAT, payment done for 12 months
A40: 109 | B40: Malak | C40: JCP/25/229030 | D40: No Placement Recorded | F40: 45931
...

Sheet Placements 26
A1: SL No. | B1: Case manager | C1: Ref No | D1: Name | E1: CPR | F1: Joining Date | G1: MoL | H1: Long MoL +3 Years | I1: Gender | J1: Education | K1: Salary | L1: Position | M1: Company | N1: Employer CR No. | O1: Employement Type | P1: Comments
A2: =ROW() - ROW(Table1[[#Headers],[SL No.]]) -> 1 | B2: Husain | C2: JCP/25/172042 | D2: WALEED ABDULWAHID J ABDULAZIZ | E2: 040710890 | F2: 46028 | G2: Yes | K2: 350 | L2: Sales | M2: CENTRE POINT COLOUR | N2: 17705-34 | O2: Full time Direct Employment | P2: Payment without VAT
A3: =ROW() - ROW(Table1[[#Headers],[SL No.]]) -> 2 | B3: Meaad | C3: JCP/24/057296 | D3: ASMA MOHAMMAD ASHFAQMO DIN | E3: 010706941 | F3: 46035 | G3: Yes | I3: Female | J3: Bachelors + | K3: 500 | L3: Quality assurance specialist | M3: Konexus | N3: 116589-1 | O3: Full time Direct Employment
A4: =ROW() - ROW(Table1[[#Headers],[SL No.]]) -> 3 | B4: Malak | C4: JCP/25/218398 | D4: ZIYAD TAREQ MAJEDA ALTHAWADI | E4: 980309620 | F4: 46033 | G4: Yes | I4: Male | J4: Bachelors + | K4: 508 | L4: Sales Executive | M4: Bahrain Duty Free | N4: 119146-1 | O4: Full time Direct Employment
A5: =ROW() - ROW(Table1[[#Headers],[SL No.]]) -> 4 | B5: Zainab Mattar | C5: JCP/25/183340 | D5: AYSHA OMAR SALEH AL ALYAZEEDI | E5: 031103103 | F5: 46033 | G5: Yes | I5: Female | J5: Diploma | K5: 482 | L5: Sales Executive | M5: Bahrain Duty Free | N5: 119146-1 | O5: Full time Direct Employment
A6: =ROW() - ROW(Table1[[#Headers],[SL No.]]) -> 5 | B6: Meaad | C6: JCP/25/210558 | D6: ali abdulameer ali ali mohamed | E6: 990805476 | F6: 46041 | G6: Yes | H6: Yes | I6: Male | J6: High School | K6: 350 | L6: Cashier | M6: GRILL LAND RESTAURANT W.L.L | N6: 121532-1 | O6: Full time Direct Employment | P6: Payment without VAT
A7: =ROW() - ROW(Table1[[#Headers],[SL No.]]) -> 6 | B7: Meaad | C7: JCP/25/267702 | D7: ABBAS AHMED A ALHANNAN | E7: 920305890 | F7: 46033 | G7: Yes | I7: Male | J7: High School | K7: 350 | L7: Dispatcher | M7: Manama Steels | N7: 103226-1 | O7: Full time Direct Employment
A8: =ROW() - ROW(Table1[[#Headers],[SL No.]]) -> 7 | B8: Meaad | C8: JCP/25/267727 | D8: MAYTHAM MOHAMED JAAFAR A. MOHAMED ALI | E8: 910601313 | F8: 46033 | I8: Male | J8: High School | K8: 350 | L8: Driver | M8: Manama Steels | N8: 103226-1 | O8: Full time Direct Employment
A9: =ROW() - ROW(Table1[[#Headers],[SL No.]]) -> 8 | B9: Zainab Mattar | C9: JCP/25/204298 | D9: ABDULLA MOHAMED HOORAN MOHAMED AWAD ALENEZI | E9: 000811084 | F9: 46033 | G9: Yes | I9: Male | J9: Bachelors + | K9: 508 | L9: Sales Executive | M9: Bahrain Duty Free | N9: 119146-1 | O9: Full time Direct Employment | P9: Payment without VAT
A10: =ROW() - ROW(Table1[[#Headers],[SL No.]]) -> 9 | B10: Meaad | C10: JCP/26/268524 | D10: LULWA EZZ EBRAHIM ABDULAZIZ RASHED ALBANKI | E10: 970409397 | F10: 46033 | G10: Yes | I10: Female | J10: Bachelors + | K10: 508 | L10: Sales Executive | M10: Bahrain Duty Free | N10: 119146-1
A11: =ROW() - ROW(Table1[[#Headers],[SL No.]]) -> 10 | B11: Mahdi | C11: JCP/26/268505 | D11: YUSUF ALI YUSUF HABIB DAGHER | E11: 041001389 | F11: 46033 | I11: Male | J11: High School | K11: 482 | L11: Sales Executive | M11: Bahrain Duty Free | N11: 119146-1
A12: =ROW() - ROW(Table1[[#Headers],[SL No.]]) -> 11 | B12: Meaad | C12: JCP/26/268879 | D12: MERZA JAMEEL MIRZA ALARADI | E12: 961006579 | F12: 46033 | G12: Yes | H12: Yes | I12: Male | J12: Bachelors + | K12: 508 | L12: Sales Executive | M12: Bahrain Duty Free | N12: 119146-1 | O12: Full time Direct Employment
A13: =ROW() - ROW(Table1[[#Headers],[SL No.]]) -> 12 | B13: Mahdi | C13: JCP/26/268526 | D13: AHMED WAHEED AKHTAR M. ALI | E13: 020302720 | F13: 46033 | G13: Yes | H13: Yes | I13: Male | J13: High School | K13: 508 | L13: Sales Executive | M13: Bahrain Duty Free | N13: 119146-1 | O13: Full time Direct Employment
A14: =ROW() - ROW(Table1[[#Headers],[SL No.]]) -> 13 | B14: Malak | C14: JCP/25/219711 | D14: FATIMA HASAN ABDULLA BUHMAID | E14: 990701140 | F14: 46033 | G14: Yes | H14: Yes | I14: Female | J14: Diploma | K14: 482 | L14: Sales Executive | M14: Bahrain Duty Free | N14: 119146-1 | O14: Full time Direct Employment | P14: Payment without VAT
A15: =ROW() - ROW(Table1[[#Headers],[SL No.]]) -> 14 | B15: Husain | C15: JCP/25/219615 | D15: HUSAIN ABDULMONEM HU MOTHANNA | E15: 010207910 | F15: 46005 | G15: Yes | I15: Male | J15: High School | K15: 450 | L15: Office Assistant | M15: ALMOAYYED CLEANING & MAINTENANCE W.L.L. | N15: 47533-1 | O15: Full time Direct Employment | P15: Payment without VAT
A16: =ROW() - ROW(Table1[[#Headers],[SL No.]]) -> 15 | B16: Husain | C16: JCP/25/232927 | D16: SAYED MOHAMED SAEED HASAN ALAWI | E16: 920401961 | F16: 46005 | G16: Yes | I16: Male | J16: Bachelors + | K16: 500 | L16: Sales Executive | M16: ALMOAYYED CONTRACTING GROUP W.L.L. | N16: 43090-1 | O16: Full time Direct Employment
A17: =ROW() - ROW(Table1[[#Headers],[SL No.]]) -> 16 | B17: Husain | C17: JCP/25/214227 | D17: FATEMA WALEED HASAN SHOWIATER | E17: 020905904 | F17: 46006 | G17: Yes | I17: Female | J17: Bachelors + | K17: 500 | L17: Trainee Mechanical engineer | M17: ALMOAYYED AIR CONDITIONING W.L.L. | N17: 76980-1 | O17: Full time Direct Employment | P17: Payment without VAT
A18: =ROW() - ROW(Table1[[#Headers],[SL No.]]) -> 17 | B18: Husain | C18: JCP/25/212208 | D18: WALAA ISA A. HASAN | E18: 990900045 | F18: 45865 | G18: Yes | I18: Female | J18: Bachelors + | K18: 700 | L18: Account Manager Specialist | M18: Student Plaform | N18: 127080-1 | O18: Full time Direct Employment | P18: Payment without VAT
A19: =ROW() - ROW(Table1[[#Headers],[SL No.]]) -> 18 | B19: Meaad | C19: JCP/25/223039 | D19: SAYED ALI HASHEM E. ALQASSAB | E19: 70809119 | F19: 45956 | G19: Yes | I19: Male | J19: High School | K19: 350 | L19: Driver | M19: SIMPLEX AL MOAYYED W.L.L | N19: 58313-1 | O19: Full time Direct Employment | P19: Payment without VAT
A20: =ROW() - ROW(Table1[[#Headers],[SL No.]]) -> 19 | B20: Malak | C20: JCP/25/233228 | D20: SYED HAMID NAZIR HUSSAIN SHAH PIRZAMAN SHAH | E20: 020515189 | F20: 46054 | G20: Yes | I20: Male | J20: Diploma | K20: 430 | L20: Accountant | M20: Harmony Music Gate | N20: 50358-1 | O20: Full time Direct Employment
A21: =ROW() - ROW(Table1[[#Headers],[SL No.]]) -> 20 | B21: Dina | C21: JCP/25/233782 | D21: FATEMA JAAFAR MOHAMED FARHAN | E21: 040601854 | F21: 45939 | G21: Yes | I21: Female | J21: High School | K21: 350 | L21: Sales Lady | M21: Femi 9 | N21: 49089-3 | O21: Full time Direct Employment
A22: =ROW() - ROW(Table1[[#Headers],[SL No.]]) -> 21 | B22: Zainab Mattar | C22: JCP/25/262810 | D22: GHASSAN ABDULLA MAHDI MAHDI | E22: 861203992 | F22: 46040 | G22: Yes | H22: Yes | I22: Male | J22: Bachelors + | K22: 800 | L22: Senior Accountant | M22: Naseef | N22: 22729-5 | O22: Full time Direct Employment
A23: =ROW() - ROW(Table1[[#Headers],[SL No.]]) -> 22 | B23: Husain | C23: JCP/26/283826 | D23: Ali Husain Seroor | E23: 941100049 | F23: 46050 | G23: Yes | H23: Yes | I23: Male | J23: High School | K23: 400 | L23: Technician | M23: Old School Garage | N23: 94591-1 | O23: Full time Direct Employment | P23: Payment with VAT
A24: =ROW() - ROW(Table1[[#Headers],[SL No.]]) -> 23 | B24: Husain | C24: JCP/25/171059 | D24: ZAINAB NASER MOHAMED MAHMOOD ALALWAANI | E24: 980602564 | F24: 46055 | G24: No | H24: No | I24: Female | J24: High School | K24: 520 | L24: Sales Executive | M24: CHALHOUS & BI,,HINDI W.L.L. | N24: 39216-1 | O24: Full time Direct Employment | P24: Payment without VAT
A25: =ROW() - ROW(Table1[[#Headers],[SL No.]]) -> 24 | B25: Husain | C25: JCP/25/171458 | D25: HUSAIN MUSTAFA ALI ALMAJED | E25: 940101645 | F25: 46055 | G25: Yes | I25: Male | J25: High School | K25: 350 | L25: STOREKEEPER | M25: CHALHOUS & BI,,HINDI W.L.L. | N25: 39216-1 | O25: Full time Direct Employment | P25: Payment without VAT
A26: =ROW() - ROW(Table1[[#Headers],[SL No.]]) -> 25 | B26: Meaad | C26: JCP/25/223860 | D26: duaa ahmedhisham t bintin | E26: 880545151 | F26: 46050 | G26: No | H26: No | I26: Female | J26: Bachelors + | K26: 580 | L26: Marketing Execituve | M26: AHMED MANSOOR AL-ALI BSC | N26: 571-2 | O26: Full time Direct Employment | P26: Payment without VAT
A27: =ROW() - ROW(Table1[[#Headers],[SL No.]]) -> 26 | B27: Meaad | C27: JCP/25/258736 | D27: Hasan Abdulnabi Tarada | E27: 991209095 | F27: 46047 | K27: 600 | L27: Auditor | M27: Sayed Junaid Alam | N27: 52-1 | O27: Full time Direct Employment
A28: =ROW() - ROW(Table1[[#Headers],[SL No.]]) -> 27 | B28: Zainab Mattar | C28: JCP/24/120499 | D28: MUSTAFA ABDULHAMEED QA HUSAIN | E28: 990200094 | F28: 46033 | G28: Yes | I28: Male | J28: Bachelors + | K28: 500 | L28: ICT Specialist | M28: Total Reliance for Construction, Trade and Consultancy | N28: 170032-1 | O28: Full time Direct Employment
A29: =ROW() - ROW(Table1[[#Headers],[SL No.]]) -> 28 | B29: Zainab Almaroom | C29: JCP/25/262077 | D29: MAHMOOD JAAFAR ABDULLA JASIM MOHAMED | E29: 891104186 | F29: 46028 | J29: Bachelors + | K29: 550 | L29: Front DEsk | M29: WPA BAHRAIN SPORTS W.L.L | N29: 175641-1 | O29: Full time Direct Employment | P29: Payment without VAT
A30: =ROW() - ROW(Table1[[#Headers],[SL No.]]) -> 29 | B30: Husain | C30: JCP/25/170479 | D30: Ali hasan Alaswami | E30: 930904079 | F30: 45692 | G30: Yes | H30: Yes | I30: Male | J30: High School | K30: 450 | L30: Safety officer | M30: Rafco | N30: 1856-1 | O30: Full time Direct Employment | P30: Payment without VAT
A31: =ROW() - ROW(Table1[[#Headers],[SL No.]]) -> 30 | B31: Husain | C31: JCP/25/213845 | D31: Sara Jamal Ahmed | E31: 970303629 | F31: 45874 | I31: Female | J31: Bachelors + | K31: 500 | L31: Consultant | M31: Propel Consult | N31: 75091-1 | O31: Insourced to Service Provider | P31: Payment without VAT
A32: =ROW() - ROW(Table1[[#Headers],[SL No.]]) -> 31 | B32: Husain | C32: JCP/26/283681 | D32: Shooq Muneer Maaroof | E32: 950401706 | F32: 46057 | G32: Yes | H32: Yes | I32: Female | J32: Bachelors + | K32: 550 | L32: Secertary | M32: ALMOAYYED CONTRACTING GROUP W.L.L. | N32: 43090-1 | O32: Full time Direct Employment
A33: =ROW() - ROW(Table1[[#Headers],[SL No.]]) -> 32 | B33: Husain | C33: JCP/25/170060 | D33: SALMAN ADEL OUN JASIM | E33: 050201182 | F33: 45697 | G33: Yes | I33: Male | J33: High School | K33: 350 | L33: Driver | M33: DRAGON BEACH HOTEL W.L.L | N33: 170835-2 | O33: Full time Direct Employment | P33: Payment without VAT
A34: =ROW() - ROW(Table1[[#Headers],[SL No.]]) -> 33 | B34: Khalifa | C34: JCP/26/271188 | D34: AMINA AYMAN S. NAJEM | E34: 010206191 | F34: 46041 | G34: Yes | I34: Female | J34: Bachelors + | K34: 600 | L34: Marketing Specialist | M34: Serious Duck | N34: 160782-1 | O34: Full time Direct Employment
A35: =ROW() - ROW(Table1[[#Headers],[SL No.]]) -> 34 | B35: Zainab Almaroom | C35: JCP/25/229821 | D35: BAYAN ADEL J. ALARAYEDH | E35: 010500308 | F35: 46041 | G35: Yes | I35: Female | J35: Bachelors + | K35: 600 | L35: Marketing Specialist | M35: Serious Duck | N35: 160782-1 | O35: Full time Direct Employment
A36: =ROW() - ROW(Table1[[#Headers],[SL No.]]) -> 35 | B36: Husain | C36: JCP/25/208891 | D36: SAYED JAAFAR EBRAHIM JAAFAR NEMAA | E36: 000804800 | F36: 46061 | I36: Male | J36: Bachelors + | K36: 530 | L36: Junior Electrical engineer | M36: ALMOAYYED CONTRACTING GROUP W.L.L. | N36: 76980-1 | O36: Full time Direct Employment
A37: =ROW() - ROW(Table1[[#Headers],[SL No.]]) -> 36 | B37: Husain | C37: JCP/25/169005 | D37: YASER SALMAN EBRAHIM MAHDI | E37: 910401390 | F37: 46070 | G37: Yes | I37: Male | J37: High School | K37: 370 | L37: Forklift driver | M37: Bahrain pack | N37: 29242-01 | O37: Full time Direct Employment | P37: Payment without VAT
A38: =ROW() - ROW(Table1[[#Headers],[SL No.]]) -> 37 | B38: Meaad | C38: JCP/26/284939 | D38: Mariam Samir Ali | E38: 931200571 | F38: 46062 | K38: 670 | L38: Business Development Manager | N38: 160782-1 | O38: Full time Direct Employment
A39: =ROW() - ROW(Table1[[#Headers],[SL No.]]) -> 38 | B39: Zainab Mattar | C39: JCP/26/269393 | D39: FATEMA HASAN JASIM HASAN AHMED | E39: 990509540 | F39: 46075 | G39: Yes | I39: Female | J39: Bachelors + | K39: 500 | L39: Coordinator | M39: ALMOAYYED CONTRACTING GROUP W.L.L. | N39: 43090-1 | O39: Full time Direct Employment
A40: =ROW() - ROW(Table1[[#Headers],[SL No.]]) -> 39 | B40: Mahdi | C40: JCP/25/181038 | D40: Hessa al doserri | E40: 001004310 | F40: 46071 | G40: Yes | I40: Female | J40: Bachelors + | K40: 600 | L40: HR officer | M40: Braxtone insurance | N40: 169147-1 | O40: Full time Direct Employment
...

Sheet Claims 26
A1: SL No. | B1: Case manager | C1: Ref No | D1: Name | E1: Joining Date | F1: Claims Status | G1: Dispute | H1: Disupute Comment | I1: Placement Fee & Variables | J1: Placement claim Highlight | K1: 6 Months | L1: 6M Stat | M1: 6 Months Claim | N1: Highlight rule 6M | O1: 12 Months | P1: 12 Months Claim | Q1: 12 M Stat | R1: Highlight rule 12 M | S1: Total Stat | T1: Total first claim | U1: Placement Fee | V1: MoL | W1: Long MoL | X1: Gender | Y1: Education | Z1: Salary
A2: =Table1[[#This Row],[SL No.]] -> 1 | B2: =Table1[[#This Row],[Case manager]] -> Husain | C2: =Table1[[#This Row],[Ref No]] -> JCP/25/172042 | D2: =Table1[[#This Row],[Name]] -> WALEED ABDULWAHID J ABDULAZIZ | E2: ='Placements 26'!F2 -> 46028 | F2: =IF(S2>=1,"Claimable","Claimed") -> Claimable | G2: No | I2: 46042 | J2: =IF(Table3[[#This Row],[Placement Fee & Variables]]>0,0,1) -> 0 | K2: =Table3[[#This Row],[Joining Date]]+180 -> 46208 | L2: =IF(AND(M2="", K2<=TODAY()), "Claimable", "") -> Claimable | N2: =IF(Table3[[#This Row],[6M Stat]]="Claimable",1,0) -> 1 | O2: =Table3[[#This Row],[Joining Date]]+365 -> 46393 | Q2: =IF(AND(P2="", O2<=TODAY()), "Claimable", "") | R2: =IF(Table3[[#This Row],[12 M Stat]]="Claimable",1,0) -> 0 | S2: =Table3[[#This Row],[Placement claim Highlight]]+Table3[[#This Row],[Highlight rule 6M]]+Table3[[#This Row],[Highlight rule 12 M]] -> 1 | T2: =SUM(Table3[[#This Row],[Placement Fee]:[Salary]]) -> 605 | U2: 550 | V2: =IF(Table1[[#This Row],[MoL]]="Yes",55,0) -> 55 | W2: =IF(Table1[[#This Row],[Long MoL +3 Years]]="Yes",137.5,0) -> 0 | X2: =IF(Table1[[#This Row],[Gender]]="Female",137.5,0) -> 0 | Y2: =IF(Table1[[#This Row],[Education]]="Bachelors +",55,0) -> 0 | Z2: =IF(Table1[[#This Row],[Salary]]>=600,82.5,0) -> 0
A3: =Table1[[#This Row],[SL No.]] -> 2 | B3: =Table1[[#This Row],[Case manager]] -> Meaad | C3: =Table1[[#This Row],[Ref No]] -> JCP/24/057296 | D3: =Table1[[#This Row],[Name]] -> ASMA MOHAMMAD ASHFAQMO DIN | E3: ='Placements 26'!F3 -> 46035 | F3: =IF(S3>=1,"Claimable","Claimed") -> Claimable | G3: No | I3: 46042 | J3: =IF(Table3[[#This Row],[Placement Fee & Variables]]>0,0,1) -> 0 | K3: =Table3[[#This Row],[Joining Date]]+180 -> 46215 | L3: =IF(AND(M3="", K3<=TODAY()), "Claimable", "") -> Claimable | N3: =IF(Table3[[#This Row],[6M Stat]]="Claimable",1,0) -> 1 | O3: =Table3[[#This Row],[Joining Date]]+365 -> 46400 | Q3: =IF(AND(P3="", O3<=TODAY()), "Claimable", "") | R3: =IF(Table3[[#This Row],[12 M Stat]]="Claimable",1,0) -> 0 | S3: =Table3[[#This Row],[Placement claim Highlight]]+Table3[[#This Row],[Highlight rule 6M]]+Table3[[#This Row],[Highlight rule 12 M]] -> 1 | T3: =SUM(Table3[[#This Row],[Placement Fee]:[Salary]]) -> 797.5 | U3: 550 | V3: =IF(Table1[[#This Row],[MoL]]="Yes",55,0) -> 55 | W3: =IF(Table1[[#This Row],[Long MoL +3 Years]]="Yes",137.5,0) -> 0 | X3: =IF(Table1[[#This Row],[Gender]]="Female",137.5,0) -> 137.5 | Y3: =IF(Table1[[#This Row],[Education]]="Bachelors +",55,0) -> 55 | Z3: =IF(Table1[[#This Row],[Salary]]>=600,82.5,0) -> 0
A4: =Table1[[#This Row],[SL No.]] -> 3 | B4: =Table1[[#This Row],[Case manager]] -> Malak | C4: =Table1[[#This Row],[Ref No]] -> JCP/25/218398 | D4: =Table1[[#This Row],[Name]] -> ZIYAD TAREQ MAJEDA ALTHAWADI | E4: ='Placements 26'!F4 -> 46033 | F4: =IF(S4>=1,"Claimable","Claimed") -> Claimed | G4: No | I4: 46042 | J4: =IF(Table3[[#This Row],[Placement Fee & Variables]]>0,0,1) -> 0 | K4: =Table3[[#This Row],[Joining Date]]+180 -> 46213 | L4: =IF(AND(M4="", K4<=TODAY()), "Claimable", "") | M4: 46245 | N4: =IF(Table3[[#This Row],[6M Stat]]="Claimable",1,0) -> 0 | O4: =Table3[[#This Row],[Joining Date]]+365 -> 46398 | Q4: =IF(AND(P4="", O4<=TODAY()), "Claimable", "") | R4: =IF(Table3[[#This Row],[12 M Stat]]="Claimable",1,0) -> 0 | S4: =Table3[[#This Row],[Placement claim Highlight]]+Table3[[#This Row],[Highlight rule 6M]]+Table3[[#This Row],[Highlight rule 12 M]] -> 0 | T4: =SUM(Table3[[#This Row],[Placement Fee]:[Salary]]) -> 110 | V4: =IF(Table1[[#This Row],[MoL]]="Yes",55,0) -> 55 | W4: =IF(Table1[[#This Row],[Long MoL +3 Years]]="Yes",137.5,0) -> 0 | X4: =IF(Table1[[#This Row],[Gender]]="Female",137.5,0) -> 0 | Y4: =IF(Table1[[#This Row],[Education]]="Bachelors +",55,0) -> 55 | Z4: =IF(Table1[[#This Row],[Salary]]>=600,82.5,0) -> 0
A5: =Table1[[#This Row],[SL No.]] -> 4 | B5: =Table1[[#This Row],[Case manager]] -> Zainab Mattar | C5: =Table1[[#This Row],[Ref No]] -> JCP/25/183340 | D5: =Table1[[#This Row],[Name]] -> AYSHA OMAR SALEH AL ALYAZEEDI | E5: 46033 | F5: =IF(S5>=1,"Claimable","Claimed") -> Claimable | G5: No | I5: 46042 | J5: =IF(Table3[[#This Row],[Placement Fee & Variables]]>0,0,1) -> 0 | K5: =Table3[[#This Row],[Joining Date]]+180 -> 46213 | L5: =IF(AND(M5="", K5<=TODAY()), "Claimable", "") -> Claimable | N5: =IF(Table3[[#This Row],[6M Stat]]="Claimable",1,0) -> 1 | O5: =Table3[[#This Row],[Joining Date]]+365 -> 46398 | Q5: =IF(AND(P5="", O5<=TODAY()), "Claimable", "") | R5: =IF(Table3[[#This Row],[12 M Stat]]="Claimable",1,0) -> 0 | S5: =Table3[[#This Row],[Placement claim Highlight]]+Table3[[#This Row],[Highlight rule 6M]]+Table3[[#This Row],[Highlight rule 12 M]] -> 1 | T5: =SUM(Table3[[#This Row],[Placement Fee]:[Salary]]) -> 192.5 | V5: =IF(Table1[[#This Row],[MoL]]="Yes",55,0) -> 55 | W5: =IF(Table1[[#This Row],[Long MoL +3 Years]]="Yes",137.5,0) -> 0 | X5: =IF(Table1[[#This Row],[Gender]]="Female",137.5,0) -> 137.5 | Y5: =IF(Table1[[#This Row],[Education]]="Bachelors +",55,0) -> 0 | Z5: =IF(Table1[[#This Row],[Salary]]>=600,82.5,0) -> 0
A6: =Table1[[#This Row],[SL No.]] -> 5 | B6: =Table1[[#This Row],[Case manager]] -> Meaad | C6: =Table1[[#This Row],[Ref No]] -> JCP/25/210558 | D6: =Table1[[#This Row],[Name]] -> ali abdulameer ali ali mohamed | E6: 46033 | F6: =IF(S6>=1,"Claimable","Claimed") -> Claimable | G6: No | I6: 46043 | J6: =IF(Table3[[#This Row],[Placement Fee & Variables]]>0,0,1) -> 0 | K6: =Table3[[#This Row],[Joining Date]]+180 -> 46213 | L6: =IF(AND(M6="", K6<=TODAY()), "Claimable", "") -> Claimable | N6: =IF(Table3[[#This Row],[6M Stat]]="Claimable",1,0) -> 1 | O6: =Table3[[#This Row],[Joining Date]]+365 -> 46398 | Q6: =IF(AND(P6="", O6<=TODAY()), "Claimable", "") | R6: =IF(Table3[[#This Row],[12 M Stat]]="Claimable",1,0) -> 0 | S6: =Table3[[#This Row],[Placement claim Highlight]]+Table3[[#This Row],[Highlight rule 6M]]+Table3[[#This Row],[Highlight rule 12 M]] -> 1 | T6: =SUM(Table3[[#This Row],[Placement Fee]:[Salary]]) -> 192.5 | V6: =IF(Table1[[#This Row],[MoL]]="Yes",55,0) -> 55 | W6: =IF(Table1[[#This Row],[Long MoL +3 Years]]="Yes",137.5,0) -> 137.5 | X6: =IF(Table1[[#This Row],[Gender]]="Female",137.5,0) -> 0 | Y6: =IF(Table1[[#This Row],[Education]]="Bachelors +",55,0) -> 0 | Z6: =IF(Table1[[#This Row],[Salary]]>=600,82.5,0) -> 0
A7: =Table1[[#This Row],[SL No.]] -> 6 | B7: =Table1[[#This Row],[Case manager]] -> Meaad | C7: =Table1[[#This Row],[Ref No]] -> JCP/25/267702 | D7: =Table1[[#This Row],[Name]] -> ABBAS AHMED A ALHANNAN | E7: ='Placements 26'!F7 -> 46033 | F7: =IF(S7>=1,"Claimable","Claimed") -> Claimed | G7: No | I7: 46044 | J7: =IF(Table3[[#This Row],[Placement Fee & Variables]]>0,0,1) -> 0 | K7: =Table3[[#This Row],[Joining Date]]+180 -> 46213 | L7: =IF(AND(M7="", K7<=TODAY()), "Claimable", "") | M7: 46216 | N7: =IF(Table3[[#This Row],[6M Stat]]="Claimable",1,0) -> 0 | O7: =Table3[[#This Row],[Joining Date]]+365 -> 46398 | Q7: =IF(AND(P7="", O7<=TODAY()), "Claimable", "") | R7: =IF(Table3[[#This Row],[12 M Stat]]="Claimable",1,0) -> 0 | S7: =Table3[[#This Row],[Placement claim Highlight]]+Table3[[#This Row],[Highlight rule 6M]]+Table3[[#This Row],[Highlight rule 12 M]] -> 0 | T7: =SUM(Table3[[#This Row],[Placement Fee]:[Salary]]) -> 55 | V7: =IF(Table1[[#This Row],[MoL]]="Yes",55,0) -> 55 | W7: =IF(Table1[[#This Row],[Long MoL +3 Years]]="Yes",137.5,0) -> 0 | X7: =IF(Table1[[#This Row],[Gender]]="Female",137.5,0) -> 0 | Y7: =IF(Table1[[#This Row],[Education]]="Bachelors +",55,0) -> 0 | Z7: =IF(Table1[[#This Row],[Salary]]>=600,82.5,0) -> 0
A8: =Table1[[#This Row],[SL No.]] -> 7 | B8: =Table1[[#This Row],[Case manager]] -> Meaad | C8: =Table1[[#This Row],[Ref No]] -> JCP/25/267727 | D8: =Table1[[#This Row],[Name]] -> MAYTHAM MOHAMED JAAFAR A. MOHAMED ALI | E8: ='Placements 26'!F8 -> 46033 | F8: =IF(S8>=1,"Claimable","Claimed") -> Claimed | G8: No | I8: 46044 | J8: =IF(Table3[[#This Row],[Placement Fee & Variables]]>0,0,1) -> 0 | K8: =Table3[[#This Row],[Joining Date]]+180 -> 46213 | L8: =IF(AND(M8="", K8<=TODAY()), "Claimable", "") | M8: 46216 | N8: =IF(Table3[[#This Row],[6M Stat]]="Claimable",1,0) -> 0 | O8: =Table3[[#This Row],[Joining Date]]+365 -> 46398 | Q8: =IF(AND(P8="", O8<=TODAY()), "Claimable", "") | R8: =IF(Table3[[#This Row],[12 M Stat]]="Claimable",1,0) -> 0 | S8: =Table3[[#This Row],[Placement claim Highlight]]+Table3[[#This Row],[Highlight rule 6M]]+Table3[[#This Row],[Highlight rule 12 M]] -> 0 | T8: =SUM(Table3[[#This Row],[Placement Fee]:[Salary]]) -> 0 | V8: =IF(Table1[[#This Row],[MoL]]="Yes",55,0) -> 0 | W8: =IF(Table1[[#This Row],[Long MoL +3 Years]]="Yes",137.5,0) -> 0 | X8: =IF(Table1[[#This Row],[Gender]]="Female",137.5,0) -> 0 | Y8: =IF(Table1[[#This Row],[Education]]="Bachelors +",55,0) -> 0 | Z8: =IF(Table1[[#This Row],[Salary]]>=600,82.5,0) -> 0
A9: =Table1[[#This Row],[SL No.]] -> 8 | B9: =Table1[[#This Row],[Case manager]] -> Zainab Mattar | C9: =Table1[[#This Row],[Ref No]] -> JCP/25/204298 | D9: =Table1[[#This Row],[Name]] -> ABDULLA MOHAMED HOORAN MOHAMED AWAD ALENEZI | E9: ='Placements 26'!F9 -> 46033 | F9: =IF(S9>=1,"Claimable","Claimed") -> Claimable | G9: No | I9: 46044 | J9: =IF(Table3[[#This Row],[Placement Fee & Variables]]>0,0,1) -> 0 | K9: =Table3[[#This Row],[Joining Date]]+180 -> 46213 | L9: =IF(AND(M9="", K9<=TODAY()), "Claimable", "") -> Claimable | N9: =IF(Table3[[#This Row],[6M Stat]]="Claimable",1,0) -> 1 | O9: =Table3[[#This Row],[Joining Date]]+365 -> 46398 | Q9: =IF(AND(P9="", O9<=TODAY()), "Claimable", "") | R9: =IF(Table3[[#This Row],[12 M Stat]]="Claimable",1,0) -> 0 | S9: =Table3[[#This Row],[Placement claim Highlight]]+Table3[[#This Row],[Highlight rule 6M]]+Table3[[#This Row],[Highlight rule 12 M]] -> 1 | T9: =SUM(Table3[[#This Row],[Placement Fee]:[Salary]]) -> 110 | V9: =IF(Table1[[#This Row],[MoL]]="Yes",55,0) -> 55 | W9: =IF(Table1[[#This Row],[Long MoL +3 Years]]="Yes",137.5,0) -> 0 | X9: =IF(Table1[[#This Row],[Gender]]="Female",137.5,0) -> 0 | Y9: =IF(Table1[[#This Row],[Education]]="Bachelors +",55,0) -> 55 | Z9: =IF(Table1[[#This Row],[Salary]]>=600,82.5,0) -> 0
A10: =Table1[[#This Row],[SL No.]] -> 9 | B10: =Table1[[#This Row],[Case manager]] -> Meaad | C10: =Table1[[#This Row],[Ref No]] -> JCP/26/268524 | D10: =Table1[[#This Row],[Name]] -> LULWA EZZ EBRAHIM ABDULAZIZ RASHED ALBANKI | E10: ='Placements 26'!F10 -> 46033 | F10: =IF(S10>=1,"Claimable","Claimed") -> Claimed | G10: No | I10: 46131 | J10: =IF(Table3[[#This Row],[Placement Fee & Variables]]>0,0,1) -> 0 | K10: =Table3[[#This Row],[Joining Date]]+180 -> 46213 | L10: =IF(AND(M10="", K10<=TODAY()), "Claimable", "") | M10: 46188 | N10: =IF(Table3[[#This Row],[6M Stat]]="Claimable",1,0) -> 0 | O10: =Table3[[#This Row],[Joining Date]]+365 -> 46398 | Q10: =IF(AND(P10="", O10<=TODAY()), "Claimable", "") | R10: =IF(Table3[[#This Row],[12 M Stat]]="Claimable",1,0) -> 0 | S10: =Table3[[#This Row],[Placement claim Highlight]]+Table3[[#This Row],[Highlight rule 6M]]+Table3[[#This Row],[Highlight rule 12 M]] -> 0 | T10: =SUM(Table3[[#This Row],[Placement Fee]:[Salary]]) -> 247.5 | V10: =IF(Table1[[#This Row],[MoL]]="Yes",55,0) -> 55 | W10: =IF(Table1[[#This Row],[Long MoL +3 Years]]="Yes",137.5,0) -> 0 | X10: =IF(Table1[[#This Row],[Gender]]="Female",137.5,0) -> 137.5 | Y10: =IF(Table1[[#This Row],[Education]]="Bachelors +",55,0) -> 55 | Z10: =IF(Table1[[#This Row],[Salary]]>=600,82.5,0) -> 0
A11: =Table1[[#This Row],[SL No.]] -> 10 | B11: =Table1[[#This Row],[Case manager]] -> Mahdi | C11: =Table1[[#This Row],[Ref No]] -> JCP/26/268505 | D11: =Table1[[#This Row],[Name]] -> YUSUF ALI YUSUF HABIB DAGHER | E11: ='Placements 26'!F11 -> 46033 | F11: =IF(S11>=1,"Claimable","Claimed") -> Claimable | G11: No | I11: 46131 | J11: =IF(Table3[[#This Row],[Placement Fee & Variables]]>0,0,1) -> 0 | K11: =Table3[[#This Row],[Joining Date]]+180 -> 46213 | L11: =IF(AND(M11="", K11<=TODAY()), "Claimable", "") -> Claimable | N11: =IF(Table3[[#This Row],[6M Stat]]="Claimable",1,0) -> 1 | O11: =Table3[[#This Row],[Joining Date]]+365 -> 46398 | Q11: =IF(AND(P11="", O11<=TODAY()), "Claimable", "") | R11: =IF(Table3[[#This Row],[12 M Stat]]="Claimable",1,0) -> 0 | S11: =Table3[[#This Row],[Placement claim Highlight]]+Table3[[#This Row],[Highlight rule 6M]]+Table3[[#This Row],[Highlight rule 12 M]] -> 1 | T11: =SUM(Table3[[#This Row],[Placement Fee]:[Salary]]) -> 0 | V11: =IF(Table1[[#This Row],[MoL]]="Yes",55,0) -> 0 | W11: =IF(Table1[[#This Row],[Long MoL +3 Years]]="Yes",137.5,0) -> 0 | X11: =IF(Table1[[#This Row],[Gender]]="Female",137.5,0) -> 0 | Y11: =IF(Table1[[#This Row],[Education]]="Bachelors +",55,0) -> 0 | Z11: =IF(Table1[[#This Row],[Salary]]>=600,82.5,0) -> 0
A12: =Table1[[#This Row],[SL No.]] -> 11 | B12: =Table1[[#This Row],[Case manager]] -> Meaad | C12: =Table1[[#This Row],[Ref No]] -> JCP/26/268879 | D12: =Table1[[#This Row],[Name]] -> MERZA JAMEEL MIRZA ALARADI | E12: ='Placements 26'!F12 -> 46033 | F12: =IF(S12>=1,"Claimable","Claimed") -> Claimed | G12: No | I12: 46044 | J12: =IF(Table3[[#This Row],[Placement Fee & Variables]]>0,0,1) -> 0 | K12: =Table3[[#This Row],[Joining Date]]+180 -> 46213 | L12: =IF(AND(M12="", K12<=TODAY()), "Claimable", "") | M12: 46208 | N12: =IF(Table3[[#This Row],[6M Stat]]="Claimable",1,0) -> 0 | O12: =Table3[[#This Row],[Joining Date]]+365 -> 46398 | Q12: =IF(AND(P12="", O12<=TODAY()), "Claimable", "") | R12: =IF(Table3[[#This Row],[12 M Stat]]="Claimable",1,0) -> 0 | S12: =Table3[[#This Row],[Placement claim Highlight]]+Table3[[#This Row],[Highlight rule 6M]]+Table3[[#This Row],[Highlight rule 12 M]] -> 0 | T12: =SUM(Table3[[#This Row],[Placement Fee]:[Salary]]) -> 247.5 | V12: =IF(Table1[[#This Row],[MoL]]="Yes",55,0) -> 55 | W12: =IF(Table1[[#This Row],[Long MoL +3 Years]]="Yes",137.5,0) -> 137.5 | X12: =IF(Table1[[#This Row],[Gender]]="Female",137.5,0) -> 0 | Y12: =IF(Table1[[#This Row],[Education]]="Bachelors +",55,0) -> 55 | Z12: =IF(Table1[[#This Row],[Salary]]>=600,82.5,0) -> 0
A13: =Table1[[#This Row],[SL No.]] -> 12 | B13: =Table1[[#This Row],[Case manager]] -> Mahdi | C13: =Table1[[#This Row],[Ref No]] -> JCP/26/268526 | D13: =Table1[[#This Row],[Name]] -> AHMED WAHEED AKHTAR M. ALI | E13: ='Placements 26'!F13 -> 46033 | F13: =IF(S13>=1,"Claimable","Claimed") -> Claimable | G13: No | I13: 46043 | J13: =IF(Table3[[#This Row],[Placement Fee & Variables]]>0,0,1) -> 0 | K13: =Table3[[#This Row],[Joining Date]]+180 -> 46213 | L13: =IF(AND(M13="", K13<=TODAY()), "Claimable", "") -> Claimable | N13: =IF(Table3[[#This Row],[6M Stat]]="Claimable",1,0) -> 1 | O13: =Table3[[#This Row],[Joining Date]]+365 -> 46398 | Q13: =IF(AND(P13="", O13<=TODAY()), "Claimable", "") | R13: =IF(Table3[[#This Row],[12 M Stat]]="Claimable",1,0) -> 0 | S13: =Table3[[#This Row],[Placement claim Highlight]]+Table3[[#This Row],[Highlight rule 6M]]+Table3[[#This Row],[Highlight rule 12 M]] -> 1 | T13: =SUM(Table3[[#This Row],[Placement Fee]:[Salary]]) -> 192.5 | V13: =IF(Table1[[#This Row],[MoL]]="Yes",55,0) -> 55 | W13: =IF(Table1[[#This Row],[Long MoL +3 Years]]="Yes",137.5,0) -> 137.5 | X13: =IF(Table1[[#This Row],[Gender]]="Female",137.5,0) -> 0 | Y13: =IF(Table1[[#This Row],[Education]]="Bachelors +",55,0) -> 0 | Z13: =IF(Table1[[#This Row],[Salary]]>=600,82.5,0) -> 0
A14: =Table1[[#This Row],[SL No.]] -> 13 | B14: =Table1[[#This Row],[Case manager]] -> Malak | C14: =Table1[[#This Row],[Ref No]] -> JCP/25/219711 | D14: =Table1[[#This Row],[Name]] -> FATIMA HASAN ABDULLA BUHMAID | E14: ='Placements 26'!F14 -> 46033 | F14: =IF(S14>=1,"Claimable","Claimed") -> Claimed | G14: No | I14: 46044 | J14: =IF(Table3[[#This Row],[Placement Fee & Variables]]>0,0,1) -> 0 | K14: =Table3[[#This Row],[Joining Date]]+180 -> 46213 | L14: =IF(AND(M14="", K14<=TODAY()), "Claimable", "") | M14: 46245 | N14: =IF(Table3[[#This Row],[6M Stat]]="Claimable",1,0) -> 0 | O14: =Table3[[#This Row],[Joining Date]]+365 -> 46398 | Q14: =IF(AND(P14="", O14<=TODAY()), "Claimable", "") | R14: =IF(Table3[[#This Row],[12 M Stat]]="Claimable",1,0) -> 0 | S14: =Table3[[#This Row],[Placement claim Highlight]]+Table3[[#This Row],[Highlight rule 6M]]+Table3[[#This Row],[Highlight rule 12 M]] -> 0 | T14: =SUM(Table3[[#This Row],[Placement Fee]:[Salary]]) -> 330 | V14: =IF(Table1[[#This Row],[MoL]]="Yes",55,0) -> 55 | W14: =IF(Table1[[#This Row],[Long MoL +3 Years]]="Yes",137.5,0) -> 137.5 | X14: =IF(Table1[[#This Row],[Gender]]="Female",137.5,0) -> 137.5 | Y14: =IF(Table1[[#This Row],[Education]]="Bachelors +",55,0) -> 0 | Z14: =IF(Table1[[#This Row],[Salary]]>=600,82.5,0) -> 0
A15: =Table1[[#This Row],[SL No.]] -> 14 | B15: =Table1[[#This Row],[Case manager]] -> Husain | C15: =Table1[[#This Row],[Ref No]] -> JCP/25/219615 | D15: =Table1[[#This Row],[Name]] -> HUSAIN ABDULMONEM HU MOTHANNA | E15: ='Placements 26'!F15 -> 46005 | F15: =IF(S15>=1,"Claimable","Claimed") -> Claimable | G15: No | I15: 46040 | J15: =IF(Table3[[#This Row],[Placement Fee & Variables]]>0,0,1) -> 0 | K15: =Table3[[#This Row],[Joining Date]]+180 -> 46185 | L15: =IF(AND(M15="", K15<=TODAY()), "Claimable", "") -> Claimable | N15: =IF(Table3[[#This Row],[6M Stat]]="Claimable",1,0) -> 1 | O15: =Table3[[#This Row],[Joining Date]]+365 -> 46370 | Q15: =IF(AND(P15="", O15<=TODAY()), "Claimable", "") | R15: =IF(Table3[[#This Row],[12 M Stat]]="Claimable",1,0) -> 0 | S15: =Table3[[#This Row],[Placement claim Highlight]]+Table3[[#This Row],[Highlight rule 6M]]+Table3[[#This Row],[Highlight rule 12 M]] -> 1 | T15: =SUM(Table3[[#This Row],[Placement Fee]:[Salary]]) -> 55 | V15: =IF(Table1[[#This Row],[MoL]]="Yes",55,0) -> 55 | W15: =IF(Table1[[#This Row],[Long MoL +3 Years]]="Yes",137.5,0) -> 0 | X15: =IF(Table1[[#This Row],[Gender]]="Female",137.5,0) -> 0 | Y15: =IF(Table1[[#This Row],[Education]]="Bachelors +",55,0) -> 0 | Z15: =IF(Table1[[#This Row],[Salary]]>=600,82.5,0) -> 0
A16: =Table1[[#This Row],[SL No.]] -> 15 | B16: =Table1[[#This Row],[Case manager]] -> Husain | C16: =Table1[[#This Row],[Ref No]] -> JCP/25/232927 | D16: =Table1[[#This Row],[Name]] -> SAYED MOHAMED SAEED HASAN ALAWI | E16: ='Placements 26'!F16 -> 46005 | F16: =IF(S16>=1,"Claimable","Claimed") -> Claimable | G16: No | I16: 46041 | J16: =IF(Table3[[#This Row],[Placement Fee & Variables]]>0,0,1) -> 0 | K16: =Table3[[#This Row],[Joining Date]]+180 -> 46185 | L16: =IF(AND(M16="", K16<=TODAY()), "Claimable", "") -> Claimable | N16: =IF(Table3[[#This Row],[6M Stat]]="Claimable",1,0) -> 1 | O16: =Table3[[#This Row],[Joining Date]]+365 -> 46370 | Q16: =IF(AND(P16="", O16<=TODAY()), "Claimable", "") | R16: =IF(Table3[[#This Row],[12 M Stat]]="Claimable",1,0) -> 0 | S16: =Table3[[#This Row],[Placement claim Highlight]]+Table3[[#This Row],[Highlight rule 6M]]+Table3[[#This Row],[Highlight rule 12 M]] -> 1 | T16: =SUM(Table3[[#This Row],[Placement Fee]:[Salary]]) -> 110 | V16: =IF(Table1[[#This Row],[MoL]]="Yes",55,0) -> 55 | W16: =IF(Table1[[#This Row],[Long MoL +3 Years]]="Yes",137.5,0) -> 0 | X16: =IF(Table1[[#This Row],[Gender]]="Female",137.5,0) -> 0 | Y16: =IF(Table1[[#This Row],[Education]]="Bachelors +",55,0) -> 55 | Z16: =IF(Table1[[#This Row],[Salary]]>=600,82.5,0) -> 0
A17: =Table1[[#This Row],[SL No.]] -> 16 | B17: =Table1[[#This Row],[Case manager]] -> Husain | C17: =Table1[[#This Row],[Ref No]] -> JCP/25/214227 | D17: =Table1[[#This Row],[Name]] -> FATEMA WALEED HASAN SHOWIATER | E17: ='Placements 26'!F17 -> 46006 | F17: =IF(S17>=1,"Claimable","Claimed") -> Claimable | G17: No | I17: 46042 | J17: 46042 | K17: 46043 | L17: 46044 | N17: =IF(Table3[[#This Row],[6M Stat]]="Claimable",1,0) -> 0 | O17: =Table3[[#This Row],[Joining Date]]+365 -> 46371 | Q17: =IF(AND(P17="", O17<=TODAY()), "Claimable", "") | R17: =IF(Table3[[#This Row],[12 M Stat]]="Claimable",1,0) -> 0 | S17: =Table3[[#This Row],[Placement claim Highlight]]+Table3[[#This Row],[Highlight rule 6M]]+Table3[[#This Row],[Highlight rule 12 M]] -> 46042 | T17: =SUM(Table3[[#This Row],[Placement Fee]:[Salary]]) -> 247.5 | V17: =IF(Table1[[#This Row],[MoL]]="Yes",55,0) -> 55 | W17: =IF(Table1[[#This Row],[Long MoL +3 Years]]="Yes",137.5,0) -> 0 | X17: =IF(Table1[[#This Row],[Gender]]="Female",137.5,0) -> 137.5 | Y17: =IF(Table1[[#This Row],[Education]]="Bachelors +",55,0) -> 55 | Z17: =IF(Table1[[#This Row],[Salary]]>=600,82.5,0) -> 0
A18: =Table1[[#This Row],[SL No.]] -> 17 | B18: =Table1[[#This Row],[Case manager]] -> Husain | C18: =Table1[[#This Row],[Ref No]] -> JCP/25/212208 | D18: =Table1[[#This Row],[Name]] -> WALAA ISA A. HASAN | E18: ='Placements 26'!F18 -> 45865 | F18: =IF(S18>=1,"Claimable","Claimed") -> Claimable | G18: No | H18: this payment is done for 6 months | I18: 45865 | J18: =IF(Table3[[#This Row],[Placement Fee & Variables]]>0,0,1) -> 0 | K18: =Table3[[#This Row],[Joining Date]]+180 -> 46045 | L18: =IF(AND(M18="", K18<=TODAY()), "Claimable", "") | M18: 46042 | N18: =IF(Table3[[#This Row],[6M Stat]]="Claimable",1,0) -> 0 | O18: =Table3[[#This Row],[Joining Date]]+365 -> 46230 | Q18: =IF(AND(P18="", O18<=TODAY()), "Claimable", "") -> Claimable | R18: =IF(Table3[[#This Row],[12 M Stat]]="Claimable",1,0) -> 1 | S18: =Table3[[#This Row],[Placement claim Highlight]]+Table3[[#This Row],[Highlight rule 6M]]+Table3[[#This Row],[Highlight rule 12 M]] -> 1 | T18: =SUM(Table3[[#This Row],[Placement Fee]:[Salary]]) -> 330 | V18: =IF(Table1[[#This Row],[MoL]]="Yes",55,0) -> 55 | W18: =IF(Table1[[#This Row],[Long MoL +3 Years]]="Yes",137.5,0) -> 0 | X18: =IF(Table1[[#This Row],[Gender]]="Female",137.5,0) -> 137.5 | Y18: =IF(Table1[[#This Row],[Education]]="Bachelors +",55,0) -> 55 | Z18: =IF(Table1[[#This Row],[Salary]]>=600,82.5,0) -> 82.5
A19: =Table1[[#This Row],[SL No.]] -> 18 | B19: =Table1[[#This Row],[Case manager]] -> Meaad | C19: =Table1[[#This Row],[Ref No]] -> JCP/25/223039 | D19: =Table1[[#This Row],[Name]] -> SAYED ALI HASHEM E. ALQASSAB | E19: 45956 | F19: =IF(S19>=1,"Claimable","Claimed") -> Claimed | G19: No | I19: 46049 | J19: =IF(Table3[[#This Row],[Placement Fee & Variables]]>0,0,1) -> 0 | K19: =Table3[[#This Row],[Joining Date]]+180 -> 46136 | L19: =IF(AND(M19="", K19<=TODAY()), "Claimable", "") | M19: 46216 | N19: =IF(Table3[[#This Row],[6M Stat]]="Claimable",1,0) -> 0 | O19: =Table3[[#This Row],[Joining Date]]+365 -> 46321 | Q19: =IF(AND(P19="", O19<=TODAY()), "Claimable", "") | R19: =IF(Table3[[#This Row],[12 M Stat]]="Claimable",1,0) -> 0 | S19: =Table3[[#This Row],[Placement claim Highlight]]+Table3[[#This Row],[Highlight rule 6M]]+Table3[[#This Row],[Highlight rule 12 M]] -> 0 | T19: =SUM(Table3[[#This Row],[Placement Fee]:[Salary]]) -> 55 | V19: =IF(Table1[[#This Row],[MoL]]="Yes",55,0) -> 55 | W19: =IF(Table1[[#This Row],[Long MoL +3 Years]]="Yes",137.5,0) -> 0 | X19: =IF(Table1[[#This Row],[Gender]]="Female",137.5,0) -> 0 | Y19: =IF(Table1[[#This Row],[Education]]="Bachelors +",55,0) -> 0 | Z19: =IF(Table1[[#This Row],[Salary]]>=600,82.5,0) -> 0
A20: =Table1[[#This Row],[SL No.]] -> 19 | B20: =Table1[[#This Row],[Case manager]] -> Malak | C20: =Table1[[#This Row],[Ref No]] -> JCP/25/233228 | D20: =Table1[[#This Row],[Name]] -> SYED HAMID NAZIR HUSSAIN SHAH PIRZAMAN SHAH | E20: ='Placements 26'!F20 -> 46054 | F20: Claimed | G20: No | I20: 46054 | J20: =IF(Table3[[#This Row],[Placement Fee & Variables]]>0,0,1) -> 0 | K20: =Table3[[#This Row],[Joining Date]]+180 -> 46234 | L20: =IF(AND(M20="", K20<=TODAY()), "Claimable", "") -> Claimable | N20: =IF(Table3[[#This Row],[6M Stat]]="Claimable",1,0) -> 1 | O20: =Table3[[#This Row],[Joining Date]]+365 -> 46419 | Q20: =IF(AND(P20="", O20<=TODAY()), "Claimable", "") | R20: =IF(Table3[[#This Row],[12 M Stat]]="Claimable",1,0) -> 0 | S20: =Table3[[#This Row],[Placement claim Highlight]]+Table3[[#This Row],[Highlight rule 6M]]+Table3[[#This Row],[Highlight rule 12 M]] -> 1 | T20: =SUM(Table3[[#This Row],[Placement Fee]:[Salary]]) -> 55 | V20: =IF(Table1[[#This Row],[MoL]]="Yes",55,0) -> 55 | W20: =IF(Table1[[#This Row],[Long MoL +3 Years]]="Yes",137.5,0) -> 0 | X20: =IF(Table1[[#This Row],[Gender]]="Female",137.5,0) -> 0 | Y20: =IF(Table1[[#This Row],[Education]]="Bachelors +",55,0) -> 0 | Z20: =IF(Table1[[#This Row],[Salary]]>=600,82.5,0) -> 0
A21: =Table1[[#This Row],[SL No.]] -> 20 | B21: =Table1[[#This Row],[Case manager]] -> Dina | C21: =Table1[[#This Row],[Ref No]] -> JCP/25/233782 | D21: =Table1[[#This Row],[Name]] -> FATEMA JAAFAR MOHAMED FARHAN | E21: ='Placements 26'!F21 -> 45939 | F21: =IF(S21>=1,"Claimable","Claimed") -> Claimable | G21: No | I21: 46051 | J21: =IF(Table3[[#This Row],[Placement Fee & Variables]]>0,0,1) -> 0 | K21: =Table3[[#This Row],[Joining Date]]+180 -> 46119 | L21: =IF(AND(M21="", K21<=TODAY()), "Claimable", "") | M21: 46202 | N21: =IF(Table3[[#This Row],[6M Stat]]="Claimable",1,0) -> 0 | O21: =Table3[[#This Row],[Joining Date]]+365 -> 46304 | Q21: =IF(AND(P21="", O21<=TODAY()), "Claimable", "") -> Claimable | R21: =IF(Table3[[#This Row],[12 M Stat]]="Claimable",1,0) -> 1 | S21: =Table3[[#This Row],[Placement claim Highlight]]+Table3[[#This Row],[Highlight rule 6M]]+Table3[[#This Row],[Highlight rule 12 M]] -> 1 | T21: =SUM(Table3[[#This Row],[Placement Fee]:[Salary]]) -> 192.5 | V21: =IF(Table1[[#This Row],[MoL]]="Yes",55,0) -> 55 | W21: =IF(Table1[[#This Row],[Long MoL +3 Years]]="Yes",137.5,0) -> 0 | X21: =IF(Table1[[#This Row],[Gender]]="Female",137.5,0) -> 137.5 | Y21: =IF(Table1[[#This Row],[Education]]="Bachelors +",55,0) -> 0 | Z21: =IF(Table1[[#This Row],[Salary]]>=600,82.5,0) -> 0
A22: =Table1[[#This Row],[SL No.]] -> 21 | B22: =Table1[[#This Row],[Case manager]] -> Zainab Mattar | C22: =Table1[[#This Row],[Ref No]] -> JCP/25/262810 | D22: =Table1[[#This Row],[Name]] -> GHASSAN ABDULLA MAHDI MAHDI | E22: ='Placements 26'!F22 -> 46040 | F22: =IF(S22>=1,"Claimable","Claimed") -> Claimable | G22: No | J22: =IF(Table3[[#This Row],[Placement Fee & Variables]]>0,0,1) -> 1 | K22: =Table3[[#This Row],[Joining Date]]+180 -> 46220 | L22: =IF(AND(M22="", K22<=TODAY()), "Claimable", "") -> Claimable | N22: =IF(Table3[[#This Row],[6M Stat]]="Claimable",1,0) -> 1 | O22: =Table3[[#This Row],[Joining Date]]+365 -> 46405 | Q22: =IF(AND(P22="", O22<=TODAY()), "Claimable", "") | R22: =IF(Table3[[#This Row],[12 M Stat]]="Claimable",1,0) -> 0 | S22: =Table3[[#This Row],[Placement claim Highlight]]+Table3[[#This Row],[Highlight rule 6M]]+Table3[[#This Row],[Highlight rule 12 M]] -> 2 | T22: =SUM(Table3[[#This Row],[Placement Fee]:[Salary]]) -> 330 | V22: =IF(Table1[[#This Row],[MoL]]="Yes",55,0) -> 55 | W22: =IF(Table1[[#This Row],[Long MoL +3 Years]]="Yes",137.5,0) -> 137.5 | X22: =IF(Table1[[#This Row],[Gender]]="Female",137.5,0) -> 0 | Y22: =IF(Table1[[#This Row],[Education]]="Bachelors +",55,0) -> 55 | Z22: =IF(Table1[[#This Row],[Salary]]>=600,82.5,0) -> 82.5
A23: =Table1[[#This Row],[SL No.]] -> 22 | B23: =Table1[[#This Row],[Case manager]] -> Husain | C23: =Table1[[#This Row],[Ref No]] -> JCP/26/283826 | D23: =Table1[[#This Row],[Name]] -> Ali Husain Seroor | E23: ='Placements 26'!F23 -> 46050 | F23: =IF(S23>=1,"Claimable","Claimed") -> Claimable | G23: No | I23: 46055 | J23: =IF(Table3[[#This Row],[Placement Fee & Variables]]>0,0,1) -> 0 | K23: =Table3[[#This Row],[Joining Date]]+180 -> 46230 | L23: =IF(AND(M23="", K23<=TODAY()), "Claimable", "") -> Claimable | N23: =IF(Table3[[#This Row],[6M Stat]]="Claimable",1,0) -> 1 | O23: =Table3[[#This Row],[Joining Date]]+365 -> 46415 | Q23: =IF(AND(P23="", O23<=TODAY()), "Claimable", "") | R23: =IF(Table3[[#This Row],[12 M Stat]]="Claimable",1,0) -> 0 | S23: =Table3[[#This Row],[Placement claim Highlight]]+Table3[[#This Row],[Highlight rule 6M]]+Table3[[#This Row],[Highlight rule 12 M]] -> 1 | T23: =SUM(Table3[[#This Row],[Placement Fee]:[Salary]]) -> 192.5 | V23: =IF(Table1[[#This Row],[MoL]]="Yes",55,0) -> 55 | W23: =IF(Table1[[#This Row],[Long MoL +3 Years]]="Yes",137.5,0) -> 137.5 | X23: =IF(Table1[[#This Row],[Gender]]="Female",137.5,0) -> 0 | Y23: =IF(Table1[[#This Row],[Education]]="Bachelors +",55,0) -> 0 | Z23: =IF(Table1[[#This Row],[Salary]]>=600,82.5,0) -> 0
A24: =Table1[[#This Row],[SL No.]] -> 23 | B24: =Table1[[#This Row],[Case manager]] -> Husain | C24: =Table1[[#This Row],[Ref No]] -> JCP/25/171059 | D24: =Table1[[#This Row],[Name]] -> ZAINAB NASER MOHAMED MAHMOOD ALALWAANI | E24: ='Placements 26'!F24 -> 46055 | F24: =IF(S24>=1,"Claimable","Claimed") -> Claimed | G24: No | H24: this payment is done for 12 months | I24: 45700 | J24: =IF(Table3[[#This Row],[Placement Fee & Variables]]>0,0,1) -> 0 | K24: =Table3[[#This Row],[Joining Date]]+180 -> 46235 | L24: =IF(AND(M24="", K24<=TODAY()), "Claimable", "") | M24: 45873 | N24: =IF(Table3[[#This Row],[6M Stat]]="Claimable",1,0) -> 0 | O24: =Table3[[#This Row],[Joining Date]]+365 -> 46420 | P24: 46055 | Q24: =IF(AND(P24="", O24<=TODAY()), "Claimable", "") | R24: =IF(Table3[[#This Row],[12 M Stat]]="Claimable",1,0) -> 0 | S24: =Table3[[#This Row],[Placement claim Highlight]]+Table3[[#This Row],[Highlight rule 6M]]+Table3[[#This Row],[Highlight rule 12 M]] -> 0 | T24: =SUM(Table3[[#This Row],[Placement Fee]:[Salary]]) -> 137.5 | V24: =IF(Table1[[#This Row],[MoL]]="Yes",55,0) -> 0 | W24: =IF(Table1[[#This Row],[Long MoL +3 Years]]="Yes",137.5,0) -> 0 | X24: =IF(Table1[[#This Row],[Gender]]="Female",137.5,0) -> 137.5 | Y24: =IF(Table1[[#This Row],[Education]]="Bachelors +",55,0) -> 0 | Z24: =IF(Table1[[#This Row],[Salary]]>=600,82.5,0) -> 0
A25: =Table1[[#This Row],[SL No.]] -> 24 | B25: =Table1[[#This Row],[Case manager]] -> Husain | C25: =Table1[[#This Row],[Ref No]] -> JCP/25/171458 | D25: =Table1[[#This Row],[Name]] -> HUSAIN MUSTAFA ALI ALMAJED | E25: ='Placements 26'!F25 -> 46055 | F25: =IF(S25>=1,"Claimable","Claimed") -> Claimed | G25: No | H25: this payment is done for 12 months | I25: 45700 | J25: =IF(Table3[[#This Row],[Placement Fee & Variables]]>0,0,1) -> 0 | K25: =Table3[[#This Row],[Joining Date]]+180 -> 46235 | L25: =IF(AND(M25="", K25<=TODAY()), "Claimable", "") | M25: 45873 | N25: =IF(Table3[[#This Row],[6M Stat]]="Claimable",1,0) -> 0 | O25: =Table3[[#This Row],[Joining Date]]+365 -> 46420 | P25: 46055 | Q25: =IF(AND(P25="", O25<=TODAY()), "Claimable", "") | R25: =IF(Table3[[#This Row],[12 M Stat]]="Claimable",1,0) -> 0 | S25: =Table3[[#This Row],[Placement claim Highlight]]+Table3[[#This Row],[Highlight rule 6M]]+Table3[[#This Row],[Highlight rule 12 M]] -> 0 | T25: =SUM(Table3[[#This Row],[Placement Fee]:[Salary]]) -> 55 | V25: =IF(Table1[[#This Row],[MoL]]="Yes",55,0) -> 55 | W25: =IF(Table1[[#This Row],[Long MoL +3 Years]]="Yes",137.5,0) -> 0 | X25: =IF(Table1[[#This Row],[Gender]]="Female",137.5,0) -> 0 | Y25: =IF(Table1[[#This Row],[Education]]="Bachelors +",55,0) -> 0 | Z25: =IF(Table1[[#This Row],[Salary]]>=600,82.5,0) -> 0
A26: =Table1[[#This Row],[SL No.]] -> 25 | B26: =Table1[[#This Row],[Case manager]] -> Meaad | C26: =Table1[[#This Row],[Ref No]] -> JCP/25/223860 | D26: =Table1[[#This Row],[Name]] -> duaa ahmedhisham t bintin | E26: ='Placements 26'!F26 -> 46050 | F26: =IF(S26>=1,"Claimable","Claimed") -> Claimable | G26: Yes | H26: She resigned before registering her | J26: =IF(Table3[[#This Row],[Placement Fee & Variables]]>0,0,1) -> 1 | K26: =Table3[[#This Row],[Joining Date]]+180 -> 46230 | L26: =IF(AND(M26="", K26<=TODAY()), "Claimable", "") -> Claimable | N26: =IF(Table3[[#This Row],[6M Stat]]="Claimable",1,0) -> 1 | O26: =Table3[[#This Row],[Joining Date]]+365 -> 46415 | Q26: =IF(AND(P26="", O26<=TODAY()), "Claimable", "") | R26: =IF(Table3[[#This Row],[12 M Stat]]="Claimable",1,0) -> 0 | S26: =Table3[[#This Row],[Placement claim Highlight]]+Table3[[#This Row],[Highlight rule 6M]]+Table3[[#This Row],[Highlight rule 12 M]] -> 2 | T26: =SUM(Table3[[#This Row],[Placement Fee]:[Salary]]) -> 192.5 | V26: =IF(Table1[[#This Row],[MoL]]="Yes",55,0) -> 0 | W26: =IF(Table1[[#This Row],[Long MoL +3 Years]]="Yes",137.5,0) -> 0 | X26: =IF(Table1[[#This Row],[Gender]]="Female",137.5,0) -> 137.5 | Y26: =IF(Table1[[#This Row],[Education]]="Bachelors +",55,0) -> 55 | Z26: =IF(Table1[[#This Row],[Salary]]>=600,82.5,0) -> 0
A27: =Table1[[#This Row],[SL No.]] -> 26 | B27: =Table1[[#This Row],[Case manager]] -> Meaad | C27: =Table1[[#This Row],[Ref No]] -> JCP/25/258736 | D27: =Table1[[#This Row],[Name]] -> Hasan Abdulnabi Tarada | E27: ='Placements 26'!F27 -> 46047 | F27: =IF(S27>=1,"Claimable","Claimed") -> Claimable | G27: Yes | H27: Candidate resigned before being registerein SIO | I27: Candidate resigned before being registerein SIO | J27: =IF(Table3[[#This Row],[Placement Fee & Variables]]>0,0,1) -> 0 | K27: =Table3[[#This Row],[Joining Date]]+180 -> 46227 | L27: =IF(AND(M27="", K27<=TODAY()), "Claimable", "") -> Claimable | N27: =IF(Table3[[#This Row],[6M Stat]]="Claimable",1,0) -> 1 | O27: =Table3[[#This Row],[Joining Date]]+365 -> 46412 | P27: Candidate resigned before being registerein SIO | Q27: =IF(AND(P27="", O27<=TODAY()), "Claimable", "") | R27: =IF(Table3[[#This Row],[12 M Stat]]="Claimable",1,0) -> 0 | S27: =Table3[[#This Row],[Placement claim Highlight]]+Table3[[#This Row],[Highlight rule 6M]]+Table3[[#This Row],[Highlight rule 12 M]] -> 1 | T27: =SUM(Table3[[#This Row],[Placement Fee]:[Salary]]) -> 82.5 | V27: =IF(Table1[[#This Row],[MoL]]="Yes",55,0) -> 0 | W27: =IF(Table1[[#This Row],[Long MoL +3 Years]]="Yes",137.5,0) -> 0 | X27: =IF(Table1[[#This Row],[Gender]]="Female",137.5,0) -> 0 | Y27: =IF(Table1[[#This Row],[Education]]="Bachelors +",55,0) -> 0 | Z27: =IF(Table1[[#This Row],[Salary]]>=600,82.5,0) -> 82.5
A28: =Table1[[#This Row],[SL No.]] -> 27 | B28: =Table1[[#This Row],[Case manager]] -> Zainab Mattar | C28: =Table1[[#This Row],[Ref No]] -> JCP/24/120499 | D28: =Table1[[#This Row],[Name]] -> MUSTAFA ABDULHAMEED QA HUSAIN | E28: ='Placements 26'!F28 -> 46033 | F28: =IF(S28>=1,"Claimable","Claimed") -> Claimable | G28: No | J28: =IF(Table3[[#This Row],[Placement Fee & Variables]]>0,0,1) -> 1 | K28: =Table3[[#This Row],[Joining Date]]+180 -> 46213 | L28: =IF(AND(M28="", K28<=TODAY()), "Claimable", "") -> Claimable | N28: =IF(Table3[[#This Row],[6M Stat]]="Claimable",1,0) -> 1 | O28: =Table3[[#This Row],[Joining Date]]+365 -> 46398 | Q28: =IF(AND(P28="", O28<=TODAY()), "Claimable", "") | R28: =IF(Table3[[#This Row],[12 M Stat]]="Claimable",1,0) -> 0 | S28: =Table3[[#This Row],[Placement claim Highlight]]+Table3[[#This Row],[Highlight rule 6M]]+Table3[[#This Row],[Highlight rule 12 M]] -> 2 | T28: =SUM(Table3[[#This Row],[Placement Fee]:[Salary]]) -> 110 | V28: =IF(Table1[[#This Row],[MoL]]="Yes",55,0) -> 55 | W28: =IF(Table1[[#This Row],[Long MoL +3 Years]]="Yes",137.5,0) -> 0 | X28: =IF(Table1[[#This Row],[Gender]]="Female",137.5,0) -> 0 | Y28: =IF(Table1[[#This Row],[Education]]="Bachelors +",55,0) -> 55 | Z28: =IF(Table1[[#This Row],[Salary]]>=600,82.5,0) -> 0
